<?xml version="1.0" encoding="utf-8"?>
<!-- This URDF was automatically created by SolidWorks to URDF Exporter! Originally created by Stephen Brawner (brawner@gmail.com) 
     Commit Version: 1.6.0-4-g7f85cfe  Build Version: 1.6.7995.38578
     For more information, please see http://wiki.ros.org/sw_urdf_exporter -->
<robot
  name="Assemblage_Carcasse">
  <link
    name="base_link">
    <inertial>
      <origin
        xyz="-0.0146413480110002 -0.00386548691145756 0.178240729732439"
        rpy="0 0 0" />
      <mass
        value="3.33267945322144" />
      <inertia
        ixx="0.0181517333610918"
        ixy="-4.85574891484082E-05"
        ixz="5.00425774285397E-06"
        iyy="0.00837313791971926"
        iyz="5.6882015009383E-06"
        izz="0.0147420874175044" />
    </inertial>
    <visual>
      <origin
        xyz="0 0 0"
        rpy="0 0 0" />
      <geometry>
        <mesh
          filename="package://simulateur_robot_2016/resource/meshes/visual/base_link.STL" />
      </geometry>
      <material
        name="">
        <color
          rgba="0.792156862745098 0.819607843137255 0.933333333333333 1" />
      </material>
    </visual>
    <collision>
      <origin
        xyz="0 0 0"
        rpy="0 0 0" />
      <geometry>
        <mesh
          filename="package://simulateur_robot_2016/resource/meshes/collision/base_link.STL" />
      </geometry>
    </collision>
  </link>
  <link
    name="arm_left_link">
    <inertial>
      <origin
        xyz="-0.0219234256730727 0.0408668588964898 -0.00459163636586507"
        rpy="0 0 0" />
      <mass
        value="0.0647149467954984" />
      <inertia
        ixx="4.67716410933806E-05"
        ixy="2.65815981172808E-05"
        ixz="9.22070279415737E-09"
        iyy="8.98179886867655E-05"
        iyz="-4.36157642057634E-09"
        izz="7.03141945035451E-05" />
    </inertial>
    <visual>
      <origin
        xyz="0 0 0"
        rpy="0 0 0" />
      <geometry>
        <mesh
          filename="package://simulateur_robot_2016/resource/meshes/visual/arm_left_link.STL" />
      </geometry>
      <material
        name="">
        <color
          rgba="1 1 1 1" />
      </material>
    </visual>
    <collision>
      <origin
        xyz="0 0 0"
        rpy="0 0 0" />
      <geometry>
        <mesh
          filename="package://simulateur_robot_2016/resource/meshes/collision/arm_left_link.STL" />
      </geometry>
    </collision>
  </link>
  <joint
    name="arm_left_joint"
    type="revolute">
    <origin
      xyz="0.0985017364358357 0.0922040679520816 0.0624038969872866"
      rpy="0 0 0" />
    <parent
      link="base_link" />
    <child
      link="arm_left_link" />
    <axis
      xyz="0 0 1" />
    <limit
      lower="-2.8"
      upper="0"
      effort="5"
      velocity="3.14" />
    <dynamics
      damping="0.1"
      friction="0.1" />
  </joint>
  <link
    name="arm_right_link">
    <inertial>
      <origin
        xyz="-0.0224349166824398 -0.0405887264956425 -0.00459163777006222"
        rpy="0 0 0" />
      <mass
        value="0.0647149533507799" />
      <inertia
        ixx="4.61116949732543E-05"
        ixy="-2.60333909115722E-05"
        ixz="9.44180032386801E-09"
        iyy="9.04779432834159E-05"
        iyz="4.32425228989141E-09"
        izz="7.03141982555891E-05" />
    </inertial>
    <visual>
      <origin
        xyz="0 0 0"
        rpy="0 0 0" />
      <geometry>
        <mesh
          filename="package://simulateur_robot_2016/resource/meshes/visual/arm_right_link.STL" />
      </geometry>
      <material
        name="">
        <color
          rgba="1 1 1 1" />
      </material>
    </visual>
    <collision>
      <origin
        xyz="0 0 0"
        rpy="0 0 0" />
      <geometry>
        <mesh
          filename="package://simulateur_robot_2016/resource/meshes/collision/arm_right_link.STL" />
      </geometry>
    </collision>
  </link>
  <joint
    name="arm_right_joint"
    type="revolute">
    <origin
      xyz="0.0985017364358357 -0.0921959320475785 0.0624038969872903"
      rpy="0 0 0" />
    <parent
      link="base_link" />
    <child
      link="arm_right_link" />
    <axis
      xyz="0 0 1" />
    <limit
      lower="0"
      upper="2.8"
      effort="5"
      velocity="3.14" />
    <dynamics
      damping="0.1"
      friction="0.1" />
  </joint>
  <link
    name="wheel_left_link">
    <inertial>
      <origin
        xyz="2.08166817117217E-17 0 -3.33066907387547E-16"
        rpy="0 0 0" />
      <mass
        value="0.0983946819104323" />
      <inertia
        ixx="3.36632805486067E-05"
        ixy="-3.73955107120678E-22"
        ixz="-6.61607946766921E-20"
        iyy="3.36632805486067E-05"
        iyz="-1.03152457204406E-23"
        izz="5.25673588106485E-05" />
    </inertial>
    <visual>
      <origin
        xyz="0 0 0"
        rpy="1.57 0 0" />
      <geometry>
      <cylinder length="0.030" radius="0.0325"/>
        <!-- <mesh
          filename="package://simulateur_robot_2016/resource/meshes/visual/wheel_left_link.STL" /> -->
      </geometry>
      <material
        name="">
        <color
          rgba="0.792156862745098 0.819607843137255 0.933333333333333 1" />
      </material>
    </visual>
    <collision>
      <origin
        xyz="0 0 0"
        rpy="1.57 0 0" />
      <geometry>
      <cylinder length="0.030" radius="0.0325"/>
      </geometry>
    </collision>
  </link>
  <joint
    name="wheel_left_joint"
    type="continuous">
    <origin
      xyz="-0.025498263564167 0.105870654653861 0.0205000000000037"
      rpy="0 0 0" />
    <parent
      link="base_link" />
    <child
      link="wheel_left_link" />
    <axis
      xyz="0 1 0" />
    <limit
      effort="10"
      velocity="10" />
    <dynamics
      damping="0.1"
      friction="0.1" />
  </joint>
  <link
    name="wheel_right_link">
    <inertial>
      <origin
        xyz="1.73472347597681E-17 5.55111512312578E-17 -3.19189119579733E-16"
        rpy="0 0 0" />
      <mass
        value="0.0983946819104323" />
      <inertia
        ixx="3.36632805486066E-05"
        ixy="-4.33219689953069E-23"
        ixz="-6.51151967957825E-20"
        iyy="3.36632805486066E-05"
        iyz="-2.41131579332038E-23"
        izz="5.25673588106484E-05" />
    </inertial>
    <visual>
      <origin
        xyz="0 0 0"
        rpy="1.57 0 0" />
      <geometry>
      <cylinder length="0.030" radius="0.0325"/>
        <!-- <mesh
          filename="package://simulateur_robot_2016/resource/meshes/visual/wheel_right_link.STL" /> -->
      </geometry>
      <material
        name="">
        <color
          rgba="0.792156862745098 0.819607843137255 0.933333333333333 1" />
      </material>
    </visual>
    <collision>
      <origin
        xyz="0 0 0"
        rpy="1.57 0 0" />
      <geometry>
      <cylinder length="0.030" radius="0.0325"/>
      </geometry>
    </collision>
  </link>
  <joint
    name="wheel_right_joint"
    type="continuous">
    <origin
      xyz="-0.0254982635641652 -0.109129345346139 0.0205000000000004"
      rpy="0 0 0" />
    <parent
      link="base_link" />
    <child
      link="wheel_right_link" />
    <axis
      xyz="0 1 0" />
    <limit
      effort="10"
      velocity="10" />
    <dynamics
      damping="0.1"
      friction="0.1" />
  </joint>
  <link
    name="caster1_link">
    <inertial>
      <origin
        xyz="0 -2.77555756156289E-17 0"
        rpy="0 0 0" />
      <mass
        value="0.000523598775598299" />
      <inertia
        ixx="5.23598775598299E-09"
        ixy="0"
        ixz="2.93873587705572E-39"
        iyy="5.23598775598299E-09"
        iyz="1.95759134039956E-54"
        izz="5.23598775598299E-09" />
    </inertial>
    <visual>
      <origin
        xyz="0 0 0"
        rpy="0 0 0" />
      <geometry>
      <sphere radius="0.005"/>

      </geometry>
      <material
        name="">
        <color
          rgba="0.792156862745098 0.819607843137255 0.933333333333333 1" />
      </material>
    </visual>
    <collision>
      <origin
        xyz="0 0 0"
        rpy="0 0 0" />
      <geometry>
      <sphere radius="0.005"/>

      </geometry>
    </collision>
  </link>
  <joint
    name="caster1_joint"
    type="fixed">
    <origin
      xyz="-0.0737506740004733 0.140008086490729 -0.00650000000000001"
      rpy="0 0 0" />
    <parent
      link="base_link" />
    <child
      link="caster1_link" />
    <axis
      xyz="0 0 0" />
  </joint>
  <link
    name="caster2_link">
    <inertial>
      <origin
        xyz="-1.38777878078145E-17 0 0"
        rpy="0 0 0" />
      <mass
        value="0.000523598775598299" />
      <inertia
        ixx="5.23598775598299E-09"
        ixy="0"
        ixz="2.93873587705572E-39"
        iyy="5.23598775598299E-09"
        iyz="1.95759134039956E-54"
        izz="5.23598775598299E-09" />
    </inertial>
    <visual>
      <origin
        xyz="0 0 0"
        rpy="0 0 0" />
      <geometry>
      <sphere radius="0.005"/>

      </geometry>
      <material
        name="">
        <color
          rgba="0.792156862745098 0.819607843137255 0.933333333333333 1" />
      </material>
    </visual>
    <collision>
      <origin
        xyz="0 0 0"
        rpy="0 0 0" />
      <geometry>
      <sphere radius="0.005"/>

      </geometry>
    </collision>
  </link>
  <joint
    name="caster2_joint"
    type="fixed">
    <origin
      xyz="0.0920017364358341 0.108008086490729 -0.00650000000000001"
      rpy="0 0 0" />
    <parent
      link="base_link" />
    <child
      link="caster2_link" />
    <axis
      xyz="0 0 0" />
  </joint>
  <link
    name="caster3_link">
    <inertial>
      <origin
        xyz="0 -2.77555756156289E-17 0"
        rpy="0 0 0" />
      <mass
        value="0.000523598775598299" />
      <inertia
        ixx="5.23598775598299E-09"
        ixy="0"
        ixz="2.93873587705572E-39"
        iyy="5.23598775598299E-09"
        iyz="1.95759134039956E-54"
        izz="5.23598775598299E-09" />
    </inertial>
    <visual>
      <origin
        xyz="0 0 0"
        rpy="0 0 0" />
      <geometry>
      <sphere radius="0.005"/>

      </geometry>
      <material
        name="">
        <color
          rgba="0.792156862745098 0.819607843137255 0.933333333333333 1" />
      </material>
    </visual>
    <collision>
      <origin
        xyz="0 0 0"
        rpy="0 0 0" />
      <geometry>
      <sphere radius="0.005"/>

      </geometry>
    </collision>
  </link>
  <joint
    name="caster3_joint"
    type="fixed">
    <origin
      xyz="-0.0737506740004732 -0.13999191350927 -0.00649999999999995"
      rpy="0 0 0" />
    <parent
      link="base_link" />
    <child
      link="caster3_link" />
    <axis
      xyz="0 0 0" />
  </joint>
  <link
    name="caster4_link">
    <inertial>
      <origin
        xyz="0 0 0"
        rpy="0 0 0" />
      <mass
        value="0.000523598775598299" />
      <inertia
        ixx="5.23598775598299E-09"
        ixy="0"
        ixz="2.93873587705572E-39"
        iyy="5.23598775598299E-09"
        iyz="1.95759134039956E-54"
        izz="5.23598775598299E-09" />
    </inertial>
    <visual>
      <origin
        xyz="0 0 0"
        rpy="0 0 0" />
      <geometry>
      <sphere radius="0.005"/>

      </geometry>
      <material
        name="">
        <color
          rgba="0.792156862745098 0.819607843137255 0.933333333333333 1" />
      </material>
    </visual>
    <collision>
      <origin
        xyz="0 0 0"
        rpy="0 0 0" />
      <geometry>
      <sphere radius="0.005"/>
      </geometry>
    </collision>
  </link>
  <joint
    name="caster4_joint"
    type="fixed">
    <origin
      xyz="0.0920017364358342 -0.10799191350927 -0.00650000000000001"
      rpy="0 0 0" />
    <parent
      link="base_link" />
    <child
      link="caster4_link" />
    <axis
      xyz="0 0 0" />
  </joint>
</robot>